<?xml version='1.0'?>
<robot name="base_model">

    <material name="black">
        <color rgba="0 0 0 1"/>
    </material>
    <material name="grey">
        <color rgba=".6 .6 .6 1"/>
    </material>

    <link name='chassis'>
        <inertial>
            <origin xyz="0 0 0.1" rpy="0 0 0"/>
            <mass value="1"/>
            <inertia ixx="100"  ixy="0"  ixz="0" iyy="100" iyz="0" izz="100" />
        </inertial>

        <collision>
            <origin xyz="0 0 .1" rpy="0 0 0 "/>
            <geometry>
                <box size=".4 .2 .2"/>
            </geometry>
        </collision>

        <visual>
            <origin rpy="0 0 0" xyz="0 0 0.1"/>
            <geometry>
                <box size=".4 .2 .1"/>
            </geometry>
            <material name="grey"/>
        </visual>
        <visual>
            <origin xyz="-0.15 0 0.05" />
            <geometry>
                <sphere radius=".05"/>
            </geometry>
        </visual>
    </link>

    <link name="left_wheel">
        <origin xyz="0.1 0.13 0.1" rpy="0 1.5707 1.5707"/>
        <collision>
            <geometry>
                <cylinder radius="0.1" length=".05"/>
            </geometry>
        </collision>

        <visual>
             <geometry>
                <cylinder radius="0.1" length=".05"/>
             </geometry>
        </visual>
    </link>

    <joint name="left_wheel_revolute" type="revolute">
        <origin xyz="1 0 0"/>
        <parent link="chassis"/>
        <child link="left_wheel"/>
        <axis xyz="1 0 0 " />
        <limit effort="30" velocity="1.0"/>
    </joint>
</robot>
